<?xml version="1.0" encoding="utf-8"?>
<!-- This URDF was automatically created by SolidWorks to URDF Exporter! Originally created by Stephen Brawner (brawner@gmail.com) 
     Commit Version: 1.5.1-0-g916b5db  Build Version: 1.5.7152.31018
     For more information, please see http://wiki.ros.org/sw_urdf_exporter -->
<robot
  name="2AxisPositioner">
  <link
    name="base_link">
    <inertial>
      <origin
        xyz="-1.1 -0.56584 0.00021321"
        rpy="0 0 0" />
      <mass
        value="49.206" />
      <inertia
        ixx="4.574"
        ixy="-0.072183"
        ixz="-0.0083247"
        iyy="2.9548"
        iyz="0.00042124"
        izz="4.5224" />
    </inertial>
    <visual>
      <origin
        xyz="0 0 0"
        rpy="0 0 0" />
      <geometry>
        <mesh
          filename="package://2AxisPositioner/meshes/base_link.STL" />
      </geometry>
      <material
        name="">
        <color
          rgba="0.79216 0.81961 0.93333 1" />
      </material>
    </visual>
    <collision>
      <origin
        xyz="0 0 0"
        rpy="0 0 0" />
      <geometry>
        <mesh
          filename="package://2AxisPositioner/meshes/base_link.STL" />
      </geometry>
    </collision>
  </link>
  <link
    name="link1">
    <inertial>
      <origin
        xyz="2.0125E-05 -0.31436 -0.58134"
        rpy="0 0 0" />
      <mass
        value="27.202" />
      <inertia
        ixx="1.6671"
        ixy="-4.6333E-06"
        ixz="-1.0232E-05"
        iyy="1.649"
        iyz="0.00077822"
        izz="0.86632" />
    </inertial>
    <visual>
      <origin
        xyz="0 0 0"
        rpy="0 0 0" />
      <geometry>
        <mesh
          filename="package://2AxisPositioner/meshes/link1.STL" />
      </geometry>
      <material
        name="">
        <color
          rgba="0.79216 0.81961 0.93333 1" />
      </material>
    </visual>
    <collision>
      <origin
        xyz="0 0 0"
        rpy="0 0 0" />
      <geometry>
        <mesh
          filename="package://2AxisPositioner/meshes/link1.STL" />
      </geometry>
    </collision>
  </link>
  <joint
    name="joint1"
    type="continuous">
    <origin
      xyz="0 0 0"
      rpy="1.5708 0 1.5708" />
    <parent
      link="base_link" />
    <child
      link="link1" />
    <axis
      xyz="0 0 1" />
    <limit
      lower="-3.14"
      upper="3.14"
      effort="0"
      velocity="0" />
  </joint>
  <link
    name="link2">
    <inertial>
      <origin
        xyz="-1.2886E-11 2.7336E-06 -0.013527"
        rpy="0 0 0" />
      <mass
        value="19.691" />
      <inertia
        ixx="1.1964"
        ixy="-3.1057E-11"
        ixz="-1.314E-12"
        iyy="1.1964"
        iyz="1.4844E-07"
        izz="2.3901" />
    </inertial>
    <visual>
      <origin
        xyz="0 0 0"
        rpy="0 0 0" />
      <geometry>
        <mesh
          filename="package://2AxisPositioner/meshes/link2.STL" />
      </geometry>
      <material
        name="">
        <color
          rgba="0.79216 0.81961 0.93333 1" />
      </material>
    </visual>
    <collision>
      <origin
        xyz="0 0 0"
        rpy="0 0 0" />
      <geometry>
        <mesh
          filename="package://2AxisPositioner/meshes/link2.STL" />
      </geometry>
    </collision>
  </link>
  <joint
    name="joint2"
    type="continuous">
    <origin
      xyz="0 -0.32 0"
      rpy="-1.5708 1.1078 0" />
    <parent
      link="link1" />
    <child
      link="link2" />
    <axis
      xyz="0 0 1" />
    <limit
      lower="-7.28"
      upper="7.28"
      effort="0"
      velocity="0" />
  </joint>
</robot>